Workbook

Sheet Ürün Maliyeti
A1: NİRENGİ DANIŞMANLIK | G1: emreceran.github.io/nirengi-danismanlik
A2: Ürün maliyet kartı
A3: Her ürün için bu sayfayı kopyalayın (sayfa sekmesine sağ tık → Taşı veya Kopyala).
A5: Ürün | B5: Çalışma masası 120x60
A6: Parti büyüklüğü (adet) | B6: 50
A7: Satış fiyatı (KDV hariç) | B7: 4250
A9: Malzeme | B9: Miktar / adet | C9: Fire % | D9: Birim fiyat | E9: Tutar / adet
A10: Kutu profil 40x40x2 | B10: 14.5 | C10: 0.04 | D10: =IF(A10="","",IFERROR(VLOOKUP(A10,Malzemeler!$A$6:$C$205,3,FALSE),0)) | E10: =IF(A10="","",B10*(1+N(C10))*D10)
A11: Sac 1,5 mm DKP | B11: 9 | C11: 0.08 | D11: =IF(A11="","",IFERROR(VLOOKUP(A11,Malzemeler!$A$6:$C$205,3,FALSE),0)) | E11: =IF(A11="","",B11*(1+N(C11))*D11)
A12: Kaynak teli SG2 1,2 mm | B12: 0.35 | C12: 0.1 | D12: =IF(A12="","",IFERROR(VLOOKUP(A12,Malzemeler!$A$6:$C$205,3,FALSE),0)) | E12: =IF(A12="","",B12*(1+N(C12))*D12)
A13: Elektrostatik toz boya | B13: 0.6 | C13: 0.15 | D13: =IF(A13="","",IFERROR(VLOOKUP(A13,Malzemeler!$A$6:$C$205,3,FALSE),0)) | E13: =IF(A13="","",B13*(1+N(C13))*D13)
A14: Ayak pabucu | B14: 4 | C14: 0 | D14: =IF(A14="","",IFERROR(VLOOKUP(A14,Malzemeler!$A$6:$C$205,3,FALSE),0)) | E14: =IF(A14="","",B14*(1+N(C14))*D14)
A15: Cıvata-somun seti | B15: 1 | C15: 0 | D15: =IF(A15="","",IFERROR(VLOOKUP(A15,Malzemeler!$A$6:$C$205,3,FALSE),0)) | E15: =IF(A15="","",B15*(1+N(C15))*D15)
A16: Kraft koli 60x40x40 | B16: 2 | C16: 0.02 | D16: =IF(A16="","",IFERROR(VLOOKUP(A16,Malzemeler!$A$6:$C$205,3,FALSE),0)) | E16: =IF(A16="","",B16*(1+N(C16))*D16)
D17: =IF(A17="","",IFERROR(VLOOKUP(A17,Malzemeler!$A$6:$C$205,3,FALSE),0)) | E17: =IF(A17="","",B17*(1+N(C17))*D17)
D18: =IF(A18="","",IFERROR(VLOOKUP(A18,Malzemeler!$A$6:$C$205,3,FALSE),0)) | E18: =IF(A18="","",B18*(1+N(C18))*D18)
D19: =IF(A19="","",IFERROR(VLOOKUP(A19,Malzemeler!$A$6:$C$205,3,FALSE),0)) | E19: =IF(A19="","",B19*(1+N(C19))*D19)
D20: =IF(A20="","",IFERROR(VLOOKUP(A20,Malzemeler!$A$6:$C$205,3,FALSE),0)) | E20: =IF(A20="","",B20*(1+N(C20))*D20)
D21: =IF(A21="","",IFERROR(VLOOKUP(A21,Malzemeler!$A$6:$C$205,3,FALSE),0)) | E21: =IF(A21="","",B21*(1+N(C21))*D21)
D22: =IF(A22="","",IFERROR(VLOOKUP(A22,Malzemeler!$A$6:$C$205,3,FALSE),0)) | E22: =IF(A22="","",B22*(1+N(C22))*D22)
D23: =IF(A23="","",IFERROR(VLOOKUP(A23,Malzemeler!$A$6:$C$205,3,FALSE),0)) | E23: =IF(A23="","",B23*(1+N(C23))*D23)
D24: =IF(A24="","",IFERROR(VLOOKUP(A24,Malzemeler!$A$6:$C$205,3,FALSE),0)) | E24: =IF(A24="","",B24*(1+N(C24))*D24)
A25: Malzeme toplamı | E25: =SUM(E10:E24)
A27: İstasyon | B27: Hazırlık (dk / parti) | C27: İşlem (dk / adet) | D27: Saat maliyeti | E27: Tutar / adet
A28: Kesim | B28: 30 | C28: 8 | D28: =IF(A28="",0,N(IFERROR(VLOOKUP(A28,İstasyonlar!$A$6:$H$35,8,FALSE),0))) | E28: =IF(A28="","",(N(B28)/$B$6+N(C28))/60*D28)
A29: Kaynak | B29: 20 | C29: 25 | D29: =IF(A29="",0,N(IFERROR(VLOOKUP(A29,İstasyonlar!$A$6:$H$35,8,FALSE),0))) | E29: =IF(A29="","",(N(B29)/$B$6+N(C29))/60*D29)
A30: Boya | B30: 45 | C30: 6 | D30: =IF(A30="",0,N(IFERROR(VLOOKUP(A30,İstasyonlar!$A$6:$H$35,8,FALSE),0))) | E30: =IF(A30="","",(N(B30)/$B$6+N(C30))/60*D30)
A31: Montaj | B31: 10 | C31: 15 | D31: =IF(A31="",0,N(IFERROR(VLOOKUP(A31,İstasyonlar!$A$6:$H$35,8,FALSE),0))) | E31: =IF(A31="","",(N(B31)/$B$6+N(C31))/60*D31)
A32: Paketleme | B32: 5 | C32: 4 | D32: =IF(A32="",0,N(IFERROR(VLOOKUP(A32,İstasyonlar!$A$6:$H$35,8,FALSE),0))) | E32: =IF(A32="","",(N(B32)/$B$6+N(C32))/60*D32)
D33: =IF(A33="",0,N(IFERROR(VLOOKUP(A33,İstasyonlar!$A$6:$H$35,8,FALSE),0))) | E33: =IF(A33="","",(N(B33)/$B$6+N(C33))/60*D33)
D34: =IF(A34="",0,N(IFERROR(VLOOKUP(A34,İstasyonlar!$A$6:$H$35,8,FALSE),0))) | E34: =IF(A34="","",(N(B34)/$B$6+N(C34))/60*D34)
D35: =IF(A35="",0,N(IFERROR(VLOOKUP(A35,İstasyonlar!$A$6:$H$35,8,FALSE),0))) | E35: =IF(A35="","",(N(B35)/$B$6+N(C35))/60*D35)
D36: =IF(A36="",0,N(IFERROR(VLOOKUP(A36,İstasyonlar!$A$6:$H$35,8,FALSE),0))) | E36: =IF(A36="","",(N(B36)/$B$6+N(C36))/60*D36)
D37: =IF(A37="",0,N(IFERROR(VLOOKUP(A37,İstasyonlar!$A$6:$H$35,8,FALSE),0))) | E37: =IF(A37="","",(N(B37)/$B$6+N(C37))/60*D37)
A38: İşçilik ve makine toplamı | E38: =SUM(E28:E37)
A40: Genel üretim gideri payı (malzeme + istasyon üzerine) | C40: 0.08
A42: Malzeme | E42: =E25
A43: İşçilik ve makine | E43: =E38
A44: Genel üretim gideri | E44: =(E25+E38)*C40
A45: Birim maliyet | E45: =E42+E43+E44
...

Sheet İstasyonlar
A1: NİRENGİ DANIŞMANLIK | H1: emreceran.github.io/nirengi-danismanlik
A2: Maliyet merkezleri (istasyonlar)
A3: Her istasyonun aylık giderini ve çalışma saatini girin; saat maliyeti hesaplanır.
A5: İstasyon / makine | B5: Aylık işçilik gideri | C5: Aylık amortisman | D5: Aylık enerji | E5: Aylık bakım ve diğer | F5: Toplam aylık gider | G5: Aylık fiili çalışma saati | H5: Saat maliyeti
A6: Kesim | B6: 96000 | C6: 18000 | D6: 9000 | E6: 4000 | F6: =IF(A6="","",SUM(B6:E6)) | G6: 176 | H6: =IF(OR(A6="",N(G6)=0),"",F6/G6)
A7: Kaynak | B7: 150000 | C7: 12000 | D7: 14000 | E7: 6000 | F7: =IF(A7="","",SUM(B7:E7)) | G7: 176 | H7: =IF(OR(A7="",N(G7)=0),"",F7/G7)
A8: Boya | B8: 88000 | C8: 25000 | D8: 22000 | E8: 8000 | F8: =IF(A8="","",SUM(B8:E8)) | G8: 150 | H8: =IF(OR(A8="",N(G8)=0),"",F8/G8)
A9: Montaj | B9: 120000 | C9: 4000 | D9: 2000 | E9: 2000 | F9: =IF(A9="","",SUM(B9:E9)) | G9: 176 | H9: =IF(OR(A9="",N(G9)=0),"",F9/G9)
A10: Paketleme | B10: 60000 | C10: 2000 | D10: 1000 | E10: 1000 | F10: =IF(A10="","",SUM(B10:E10)) | G10: 176 | H10: =IF(OR(A10="",N(G10)=0),"",F10/G10)
F11: =IF(A11="","",SUM(B11:E11)) | H11: =IF(OR(A11="",N(G11)=0),"",F11/G11)
F12: =IF(A12="","",SUM(B12:E12)) | H12: =IF(OR(A12="",N(G12)=0),"",F12/G12)
F13: =IF(A13="","",SUM(B13:E13)) | H13: =IF(OR(A13="",N(G13)=0),"",F13/G13)
F14: =IF(A14="","",SUM(B14:E14)) | H14: =IF(OR(A14="",N(G14)=0),"",F14/G14)
F15: =IF(A15="","",SUM(B15:E15)) | H15: =IF(OR(A15="",N(G15)=0),"",F15/G15)
F16: =IF(A16="","",SUM(B16:E16)) | H16: =IF(OR(A16="",N(G16)=0),"",F16/G16)
F17: =IF(A17="","",SUM(B17:E17)) | H17: =IF(OR(A17="",N(G17)=0),"",F17/G17)
F18: =IF(A18="","",SUM(B18:E18)) | H18: =IF(OR(A18="",N(G18)=0),"",F18/G18)
F19: =IF(A19="","",SUM(B19:E19)) | H19: =IF(OR(A19="",N(G19)=0),"",F19/G19)
F20: =IF(A20="","",SUM(B20:E20)) | H20: =IF(OR(A20="",N(G20)=0),"",F20/G20)
F21: =IF(A21="","",SUM(B21:E21)) | H21: =IF(OR(A21="",N(G21)=0),"",F21/G21)
F22: =IF(A22="","",SUM(B22:E22)) | H22: =IF(OR(A22="",N(G22)=0),"",F22/G22)
... F35: =IF(A35="","",SUM(B35:E35)) | H35: =IF(OR(A35="",N(G35)=0),"",F35/G35)

Sheet Malzemeler
A1: NİRENGİ DANIŞMANLIK | C1: emreceran.github.io/nirengi-danismanlik
A2: Malzeme fiyat listesi
A3: Güncel alış fiyatlarını (KDV hariç) girin.
A5: Malzeme | B5: Birim | C5: Birim fiyat
A6: Kutu profil 40x40x2 | B6: KG | C6: 45.9
A7: Sac 1,5 mm DKP | B7: KG | C7: 38.2
A8: Kaynak teli SG2 1,2 mm | B8: KG | C8: 112.5
A9: Elektrostatik toz boya | B9: KG | C9: 210
A10: Ayak pabucu | B10: ADET | C10: 6.5
A11: Cıvata-somun seti | B11: SET | C11: 14
A12: Kraft koli 60x40x40 | B12: ADET | C12: 27.9

Sheet Nasıl kullanılır
A1: NİRENGİ DANIŞMANLIK | B1: emreceran.github.io/nirengi-danismanlik
A2: Ürün Maliyet Hesabı
A3: Bu sayfa şablonun nasıl kullanılacağını anlatır.
A5: ■ | B5: Sarı hücreler giriş hücreleridir; kendi rakamlarınızı buraya yazın. Beyaz hücreler formüldür, değiştirmeyin.
A7: 1. | B7: İstasyonlar sayfasına üretimdeki her istasyonun (kesim, kaynak, boya vb.) aylık işçilik, amortisman, enerji ve bakım giderlerini ve aylık fiili çalışma saatini girin. Saat maliyeti otomatik hesaplanır.
A8: 2. | B8: Malzemeler sayfasına kullandığınız malzemelerin güncel alış fiyatlarını (KDV hariç) girin.
A9: 3. | B9: Ürün Maliyeti sayfasında ürünün reçetesini (malzeme, adet başına miktar, fire oranı) ve rotasını (hangi istasyonda kaç dakika) yazın. Malzeme ve istasyon adlarını listeden seçebilirsiniz.
A10: 4. | B10: Hazırlık süresi parti başına bir kez harcanan süredir (makine ayarı, kalıp değişimi). Parti büyüklüğü küçüldükçe adet başına hazırlık maliyeti artar; alttaki tablo bu etkiyi gösterir.
A11: 5. | B11: Genel üretim gideri payı, istasyonlara dağıtılmamış giderler (kalite kontrol, depo, üretim yönetimi) içindir. Oranı geçmiş yılın gerçek giderlerinden hesaplamanızı öneririz.
A12: 6. | B12: Her ürün için sayfayı kopyalayın. Birkaç ana ürünün gerçek maliyeti, fiyatlama kararları için genellikle yeterli bilgiyi verir.
A13: 7. | B13: Bu şablon yönetim kararları içindir; mali tablolardaki maliyet hesabıyla tutarlılığı mali müşavirinizle birlikte kontrol edin.
B15: Örnek veriler yalnızca şablonun nasıl çalıştığını göstermek içindir; silip kendi verinizi girebilirsiniz.
B17: Konuyla ilgili yazı
B18: https://emreceran.github.io/nirengi-danismanlik/blog/gercek-urun-maliyeti.html
B20: Takıldığınız yerde ya da sonuçları birlikte yorumlamak isterseniz: ücretsiz ilk görüşme
B21: https://emreceran.github.io/nirengi-danismanlik/iletisim.html
B23: Bu şablon genel bilgilendirme amaçlıdır ve ücretsiz olarak paylaşılabilir. © Nirengi Danışmanlık
